Workbook
Name AIC_List: NEC_Data!$Y$46:$Y$57
Name Ampacity_Al: NEC_Data!$BA$6:$BA$25
Name Ampacity_CM: NEC_Data!$BB$6:$BB$25
Name Ampacity_Cu: NEC_Data!$AZ$6:$AZ$25
Name Ampacity_Size: NEC_Data!$AY$6:$AY$25
Name ATS_List: NEC_Data!$DF$6:$DF$23
Name ATS_WCR: NEC_Data!$DG$6:$DG$23
Name Brace_List: NEC_Data!$DE$6:$DE$19
Name BranchAmpCol: Dashboard!$C$90
Name BranchCcol: Dashboard!$C$94
Name BranchCol60: NEC_Data!$AB$13
Name BranchK: Dashboard!$C$92
Name Bus_List: NEC_Data!$DD$6:$DD$22
Name Cfg_BranchMat: Dashboard!$C$47
Name Cfg_Class: Dashboard!$C$43
Name Cfg_Conduit: Dashboard!$C$50
Name Cfg_Energy_Code: 'Load Calc'!$C$14
Name Cfg_FeederMat: Dashboard!$C$48
Name Cfg_LPD_Method: 'Load Calc'!$C$15
Name Cfg_MaxNodes: NEC_Data!$CD$10
Name Cfg_MotorMult: NEC_Data!$CD$12
Name Cfg_MotorMultMCC: NEC_Data!$CD$13
Name Cfg_NEC: Dashboard!$B$14
Name Cfg_Phase: Dashboard!$C$40
Name Cfg_SCA: Dashboard!$C$72
Name Cfg_Temp: Dashboard!$C$49
Name Cfg_UtilFLA: Dashboard!$C$73
Name Cfg_UtilIscInf: Dashboard!$C$74
Name Cfg_UtilKVA: Dashboard!$C$67
Name Cfg_UtilPriV: Dashboard!$C$68
Name Cfg_UtilProvider: Dashboard!$C$65
Name Cfg_UtilTag: Dashboard!$C$64
Name Cfg_UtilXR: Dashboard!$C$71
Name Cfg_UtilZ: Dashboard!$C$70
Name Cfg_VDFeeder: NEC_Data!$CD$15
Name Cfg_VDTotal: NEC_Data!$CD$16
Name Cfg_VLN: Dashboard!$C$42
Name Cfg_Volt: Dashboard!$C$39
Name Class_List: NEC_Data!$K$46:$K$57
Name Class_Table: NEC_Data!$K$46:$N$57
Name Cond_Size: NEC_Data!$J$6:$J$28
Name Cond_Table: NEC_Data!$J$6:$U$28
Name EGC_Al: NEC_Data!$BE$6:$BE$22
Name EGC_Cu: NEC_Data!$BD$6:$BD$22
Name EGC_OCPD: NEC_Data!$BC$6:$BC$22
Name EGC_Table: NEC_Data!$W$6:$Y$24
Name Elev_DF: NEC_Data!$P$56:$Q$65
Name Equip_Demand: Dashboard!$F$101:$F$350
Name Equip_EmLen: Dashboard!$T$101:$T$350
Name Equip_FdrExist: Dashboard!$W$101:$W$350
Name Equip_FdrLen: Dashboard!$R$101:$R$350
Name Equip_FdrMat: Dashboard!$U$101:$U$350
Name Equip_FdrRace: Dashboard!$V$101:$V$350
Name Equip_FedFrom: Dashboard!$D$101:$D$350
Name Equip_List: Dashboard!$A$101:$A$350
Name Equip_Registry: Dashboard!$A$101:$J$350
Name Equip_Type: Dashboard!$B$101:$B$350
Name Equip_Volt: Dashboard!$C$101:$C$350
Name Equip_XfPriLen: Dashboard!$S$101:$S$350
Name Exist_LogBoard: IF(TRIM('Logging Demand'!$C$14&"")<>"",TRIM('Logging Demand'!$C$14&""),Exist_ServiceBoard)

Sheet Instructions
A1: INSTRUCTIONS
A2: Cradle-to-grave electrical design toolkit. Everything the ribbon does, every cell you type in, and every number it calculates — in order. Keep this tab with the project.
A3: Version 2.10 · SÄZÄN PowerCalc add-in · One chapter per ribbon section, in ribbon order. Ribbon ▸ Help ▸ Instructions jumps to any chapter; the CONTENTS links below do the same.
A4: CONTENTS
A5: 01 | B5: Getting Started | C5: How the tool is built, installing it, a ten-step quick start and the colour / cell conventions used on every sheet.
A6: 02 | B6: Project | C6: Ribbon ▸ Setup ▸ Project. The project shell, the Dashboard and its Design QA panel.
A7: 03 | B7: Load Calc | C7: Ribbon ▸ Setup ▸ Load Calc. Building loads, sections, and sending loads to the panel schedules.
A8: 04 | B8: Existing Demand | C8: Ribbon ▸ Setup ▸ Existing Demand. NEC 220.87 from utility bills or a 30-day logging study.
A9: 05 | B9: Panel Schedules | C9: Ribbon ▸ Distribution ▸ Panel Schedules. Switchboards, MCCs and panelboards; linking is done in the Distribution Map (chapter 14).
A10: 06 | B10: Transformers | C10: Ribbon ▸ Distribution ▸ Transformers. Rows derive themselves wherever a feed changes voltage.
A11: 07 | B11: Backup Power | C11: Ribbon ▸ Distribution ▸ Backup Power. Generators, transfer switches and UPS systems.
A12: 08 | B12: Feeders | C12: Ribbon ▸ Studies ▸ Feeders. One derived row per feeder: conductor, conduit, OCPD and EGC.
A13: 09 | B13: Voltage Drop | C13: Ribbon ▸ Studies ▸ Voltage Drop. Run and cumulative %VD per bus.
A14: 10 | B14: Short Circuit | C14: Ribbon ▸ Studies ▸ Short Circuit. Available fault current and AIC adequacy at every bus.
A15: 11 | B15: Arc Flash | C15: Ribbon ▸ Safety & Review ▸ Arc Flash. IEEE 1584 incident energy and PPE category per bus.
A16: 12 | B16: Studies | C16: Ribbon ▸ Safety & Review ▸ Studies. The combined read-only study view and the full refresh.
... A19: 15 | B19: Reference & Troubleshooting | C19: How the engine works, rules, troubleshooting, the code basis and the appendices.
A21: CHAPTER 01 · GETTING STARTED
A22: How the tool is built, installing it, a ten-step quick start and the colour / cell conventions used on every sheet.
B23: What this is, and how it is built
B24: Purpose | C24: A single tool that carries an electrical design from first load estimate to issued schedules: NEC Article 220 load calc, existing-building demand, panel/switchboard/MCC schedules, transformers, generator and UPS sizing, short circuit, voltage drop, arc flash, feeder sizing, a combined Studies view, and a printable report.
B25: How it ships | C25: Two parts, and neither one holds your project data. (1) THE ADD-IN — a ribbon tab and a dockable task pane, loaded by Excel from a hosted manifest. It holds the commands. (2) THE PROJECT TEMPLATE — sazan-project-template.xlsx, which holds all 19 calculation sheets with every cross-sheet formula intact and no project data. You start a project from the template; the add-in drives it. There is a third file, SGI_PowerCalc_Master_v1.xlsm, but it is the AUTHORING master that the template is generated from — only the maintainer opens it.
B26: The add-in | C26: SAZAN Panel Tree, an Office web add-in. Excel loads it from a manifest pointing at static files hosted over HTTPS, so there is nothing to install per machine beyond registering the catalog once. It adds the SÄZÄN POWERCALC ribbon tab and a task pane you can dock, float and resize. It runs on Excel for Windows, Mac and the web, and it contains no VBA — a task pane cannot run macros. See section 2 to install it.
B27: The project workbook | C27: A copy of sazan-project-template.xlsx saved under your project name. It opens WHOLE — all 19 calculation sheets, every cross-sheet formula and every defined name already in place. Nothing is copied in on demand, because the Dashboard and the modules reference each other in both directions and no single one of them works alone. It stays a plain .xlsx with no macros, so it emails and archives cleanly.
B28: The code engines | C28: NEC_Data holds the voltage systems, NEC 240.6 OCPD and fuse sizes, the NEMA receptacle library, NEC Chapter 9 Table 8 conductor properties, K and C constants, load classifications and demand factors, and standard transformer kVA. Energy_Code_Data holds lighting power densities and space types. Every dropdown and every calc in the workbook reads from these two sheets — nothing is hardcoded in a formula. Both ship inside the project template, so each project carries its own copy of the code data.
B29: The device templates | C29: TPL_Switchboard, TPL_Panelboard and TPL_MCC are master layouts, and all three travel inside the project template. When you create a device, the add-in copies the matching template within your own workbook, renames it to your device tag, and registers it on the Dashboard. Editing a template changes every device created afterwards — never devices already created.
B30: GEO_MAP | C30: Each template carries a small GEO_MAP block (far right of the sheet, grey 8 pt) listing where its name, voltage, AIC, fault, demand and voltage-drop cells live. The commands read addresses from GEO_MAP instead of hardcoding them, so a template can be re-laid-out without breaking the code. See Appendix A.
B31: The registry is the spine | C31: Every device you create gets one row in the Dashboard EQUIPMENT REGISTRY, keyed by its tag. Studies, links, roll-ups and reconciliation all find equipment by that tag — never by sheet position. If a device is not in the registry, it does not exist to the rest of the tool.
B32: Install and first-time setup
A33: 1 | B33: What you need | C33: Excel 365 on Windows, Mac or the web. The add-in's manifest.xml, and one folder your team can reach — a network share works, and a plain local folder is fine for solo testing. You do NOT need admin rights, you do NOT need macros enabled, and there is nothing to unblock.
A34: 2 | B34: Register the catalog — once per machine | C34: Put manifest.xml in that folder. Then File ▸ Options ▸ Trust Center ▸ Trust Center Settings ▸ Trusted Add-in Catalogs. Paste the FOLDER path, not the path to the manifest file itself — this is the step people get wrong. Add catalog, tick Show in Menu, OK, then restart Excel. For a team-wide rollout the maintainer can instead upload manifest.xml in the M365 admin center ▸ Settings ▸ Integrated apps, which pushes it to everyone with no per-machine step.
A35: 3 | B35: Insert the add-in | C35: Insert ▸ My Add-ins ▸ SHARED FOLDER tab ▸ SAZAN Panel Tree ▸ Add. The task pane opens docked on the right. Drag its inner edge to resize, drag the header out to float, drag it back to redock — Excel manages the dock itself.
A36: 4 | B36: Confirm it loaded | C36: You should see a top-level ribbon tab named SÄZÄN POWERCALC, and the task pane should show the black PANEL TREE band. If the tab is missing, the catalog path is wrong or Excel has not been restarted since — see section 13.
A37: 5 | B37: Get the project template | C37: Download sazan-project-template.xlsx from the repository and keep one clean copy somewhere the team can reach. Start every project by COPYING that file. Do not work from an email attachment or a Downloads folder.
A38: 6 | B38: Keep the template pristine | C38: Never type project data into the clean copy of the template — it is the source every project starts from, and if it gets polluted every future project inherits it. The same rule applies to the authoring master, SGI_PowerCalc_Master_v1.xlsm, which only the maintainer opens.
B39: Quick start — a project in ten steps
A40: 1 | B40: Start from the template | C40: Copy sazan-project-template.xlsx and save it under your project name. It already contains all 19 calculation sheets, every formula and every defined name — there is nothing to build and nothing to import.
A41: 2 | B41: Fill the project block | C41: Dashboard ▸ PROJECT INFORMATION: project name, number, client, location, engineer / PE of record, date, revision. Blue-on-grey cells only.
A42: 3 | B42: Set the system voltage | C42: Dashboard ▸ ELECTRICAL SYSTEM ▸ System Voltage (dropdown). Everything downstream — nominal V, phase, wires, L-N voltage, voltage class — derives from this one selection. Nothing calculates correctly until it is set.
A43: 4 | B43: Set design defaults | C43: Dashboard ▸ DESIGN DEFAULTS: branch and feeder conductor material (Cu/Al), termination temperature rating (60/75/90 °C), conduit type. Then UTILITY SOURCES: one column per service transformer (up to four) — tag, provider, kVA, %Z, X/R and the available fault current from each utility letter. Then BUS TIES for split-bus / main-tie-main boards.
...

Sheet Dashboard
A1: PROJECT DASHBOARD — CRADLE-TO-GRAVE ELECTRICAL DESIGN
A2: Blue text on grey = your inputs. Red = auto-calculated (do not type).
A4: PROJECT INFORMATION
F6: Module | G6: Status | H6: Key Result | I6: Sheet
A7: Project Name | F7: Load Calculation | G7: =IFERROR(IF(N(LC_DemandTotal)>0,"● Active","○ Pending"),"○ Pending") -> ○ Pending | H7: =IFERROR(IF(N(LC_DemandTotal)>0,TEXT(LC_DemandTotal,"#,##0.0")&" kVA"&IF(ISNUMBER(LC_DemandAmps)," / "&TEXT(LC_DemandAmps,"#,##0")&" A demand",""),"—"),"—") -> — | I7: Load Calc
A8: Project Number | F8: {="Utility Bills "&NECREF("220.87")&" (12-Month)"} -> Utility Bills 220.87 (12-Month) | G8: =IFERROR(IF(N('Utility Demand'!$G$36)>0,"● Active","○ Pending"),"○ Pending") -> ○ Pending | H8: =IFERROR(IF(N('Utility Demand'!$G$36)>0,TEXT('Utility Demand'!$G$36,"#,##0.0")&" kW peak / "&TEXT('Utility Demand'!$G$42,"#,##0.0")&" kVA spare","—"),"—") -> — | I8: Utility Demand
A9: Client | F9: {="Logging "&NECREF("220.87")&" (30-Day)"} -> Logging 220.87 (30-Day) | G9: =IFERROR(IF(N('Logging Demand'!$C$45)>0,"● Active","○ Pending"),"○ Pending") -> ○ Pending | H9: {=IFERROR(IF(N('Logging Demand'!$C$45)>0,TEXT('Logging Demand'!$C$45,"#,##0.0")&" kW peak / "&TEXT('Logging Demand'!$C$48,"#,##0.0")&(" kVA per "&NECREF("220.87")),"—"),"—")} -> — | I9: Logging Demand
A10: Location | F10: Generator Sizing | G10: =IF(Tog_Gen<>"ON","— not in project",IF(N(Generator!$D$40)>0,"● Active","◐ Incomplete")) -> — not in project | H10: =IF(Tog_Gen<>"ON",IF(N(LC_GenTotal)>0,TEXT(LC_GenTotal,"#,##0.0")&" kVA tagged Gen — add Generator (ribbon)","— not in project"),IF(N(Generator!$D$40)>0,IF(ISNUMBER(Generator!$D$45),TEXT(Generator!$D$45,"#,##0")&" kW gen","—")&IF(COUNTIF(Generator!$B$62:$B$69,"?*")>0," · "&COUNTIF(Generator!$B$62:$B$69,"?*")&" transfer switch(es)",""),IF(COUNTIF(Generator!$B$53:$B$58,"?*")=0,"Missing: generator unit tag (Generator ▸ Units)","Missing: loads — tag Gen on Load Calc or add manual loads"))) -> — not in project | I10: Generator
A11: Engineer / PE of Record | F11: UPS Sizing | G11: =IF(Tog_UPS<>"ON","— not in project",IF(OR(N(UPS!$C$38)>0,COUNT(UPS!$L$57:$L$64)>0),"● Active","◐ Incomplete")) -> — not in project | H11: =IF(Tog_UPS<>"ON",IF(N(LC_UPSTotal)>0,TEXT(LC_UPSTotal,"#,##0.0")&" kVA tagged UPS — add UPS (ribbon)","— not in project"),IF(OR(N(UPS!$C$38)>0,COUNT(UPS!$L$57:$L$64)>0),IF(ISNUMBER(UPS!$C$41),TEXT(UPS!$C$41,"#,##0")&" kVA module",IF(COUNT(UPS!$L$57:$L$64)>0,TEXT(SUM(UPS!$L$57:$L$64),"#,##0")&" kVA placed","—"))&IF(COUNTIF(UPS!$B$57:$B$64,"?*")>0," · "&COUNTIF(UPS!$B$57:$B$64,"?*")&" UPS system(s)",""),IF(COUNTIF(UPS!$B$48:$B$53,"?*")=0,"Missing: UPS unit tag (UPS ▸ Units)","Missing: loads — tag UPS on Load Calc, add manual loads, or place a UPS system"))) -> — not in project | I11: UPS
A12: Date | F12: Panel Schedules | G12: =IF(COUNTA(Equip_List)>0,"● Active","○ Pending") -> ○ Pending | H12: =COUNTA(Equip_List)&" equipment in registry" -> 0 equipment in registry | I12: (registry below)
A13: Revision | F13: Short Circuit / AIC | G13: =IFERROR(_xlfn.LET(_xlpm.b,COUNTA(Equip_List),_xlpm.n,COUNTIFS('Short Circuit'!$A$6:$A$255,"?*",'Short Circuit'!$C$6:$C$255,"<>0")-COUNTIFS('Short Circuit'!$A$6:$A$255,"T-*",'Short Circuit'!$R$6:$R$255,""),_xlpm.s,COUNT('Short Circuit'!$S$6:$S$255),IF(_xlpm.b=0,"○ Pending",IF(AND(_xlpm.s>0,_xlpm.s>=_xlpm.n),"● Active","◐ Incomplete"))),"◐ Incomplete") -> ○ Pending | H13: =IFERROR(_xlfn.LET(_xlpm.b,COUNTA(Equip_List),_xlpm.n,COUNTIFS('Short Circuit'!$A$6:$A$255,"?*",'Short Circuit'!$C$6:$C$255,"<>0")-COUNTIFS('Short Circuit'!$A$6:$A$255,"T-*",'Short Circuit'!$R$6:$R$255,""),_xlpm.s,COUNT('Short Circuit'!$S$6:$S$255),_xlpm.fm,COUNTIF('Short Circuit'!$T$6:$T$255,"*feeder data missing*"),IF(_xlpm.b=0,"— no equipment yet",IF(_xlpm.s>0,TEXT(MIN('Short Circuit'!$S$6:$S$255),"#,##0")&" A min AIC margin"&IF(_xlpm.s<_xlpm.n," · "&(_xlpm.n-_xlpm.s)&" of "&_xlpm.n&" bus(es) missing data",""),IF(COUNT(Util_SCAEff)=0,"Missing: utility fault current (Dashboard ▸ Utility Sources)",IF(_xlpm.n=0,"Missing: Fed From on equipment (Distribution Map)",IF(_xlpm.fm>0,"Missing: feeder load / length on "&_xlpm.fm&" feeder(s) (Feeder Schedule)","Missing: device AIC on "&_xlpm.n&" bus(es)")))))),"—") -> — no equipment yet | I13: Short Circuit
A14: NEC Edition | B14: 2023 | F14: Voltage Drop | G14: =IFERROR(IF(COUNTIFS('Voltage Drop'!$A$6:$A$255,"<>",'Voltage Drop'!$C$6:$C$255,">0")>0,"● Active","○ Pending"),"○ Pending") -> ○ Pending | H14: =IFERROR(IF(COUNTIFS('Voltage Drop'!$A$6:$A$255,"<>",'Voltage Drop'!$C$6:$C$255,">0")=0,"—",TEXT(MAX('Voltage Drop'!$H$6:$H$255),"0.00%")&" worst cumulative VD"),"—") -> — | I14: Voltage Drop
F15: Arc Flash (IEEE 1584) | G15: =IFERROR(_xlfn.LET(_xlpm.b,COUNTA(Equip_List),_xlpm.n,COUNTIFS('Short Circuit'!$A$6:$A$255,"?*",'Short Circuit'!$C$6:$C$255,"<>0"),_xlpm.r,COUNT('Arc Flash'!$B$24:$B$296),_xlpm.m,COUNT('Arc Flash'!$M$24:$M$296),IF(_xlpm.b=0,"○ Pending",IF(AND(_xlpm.m>0,_xlpm.m>=_xlpm.r,_xlpm.r>=_xlpm.n),"● Active","◐ Incomplete"))),"◐ Incomplete") -> ○ Pending | H15: =IFERROR(_xlfn.LET(_xlpm.b,COUNTA(Equip_List),_xlpm.n,COUNTIFS('Short Circuit'!$A$6:$A$255,"?*",'Short Circuit'!$C$6:$C$255,"<>0"),_xlpm.r,COUNT('Arc Flash'!$B$24:$B$296),_xlpm.m,COUNT('Arc Flash'!$M$24:$M$296),_xlpm.c,COUNT('Arc Flash'!$C$24:$C$296),IF(_xlpm.b=0,"— no equipment yet",IF(_xlpm.m>0,TEXT(MAX('Arc Flash'!$M$24:$M$296),"0.00")&" cal/cm² worst case"&IF(_xlpm.r<_xlpm.n," · run Refresh Studies ("&_xlpm.r&" of "&_xlpm.n&" buses listed)",IF(_xlpm.m<_xlpm.r," · "&(_xlpm.r-_xlpm.m)&" bus(es) missing data","")),IF(_xlpm.r<_xlpm.n,"Missing: run Refresh Studies ("&_xlpm.r&" of "&_xlpm.n&" buses listed)",IF(_xlpm.c<_xlpm.r,"Missing: bus fault from Short Circuit on "&(_xlpm.r-_xlpm.c)&" bus(es)","Missing: equipment class / clearing time (Arc Flash)"))))),"—") -> — no equipment yet | I15: Arc Flash
A17: DESIGN QA — CHECKS & VALIDATION
A18: =COUNTIF($E$21:$E$34,"✔*")&" pass · "&COUNTIF($E$21:$E$34,"⚠*")&" review · "&COUNTIF($E$21:$E$34,"✘*")&" fail · "&COUNTIF($E$21:$E$34,"—*")&" pending" -> 0 pass · 2 review · 0 fail · 12 pending
A20: # | B20: Check | C20: NEC / Basis | E20: Result
A21: 1 | B21: System voltage configured | C21: Dashboard config | E21: =IF(N(Cfg_Volt)>0,"✔ "&TEXT(Cfg_Volt,"#,##0")&" V set","⚠ Set System Voltage on Dashboard") -> ⚠ Set System Voltage on Dashboard
A22: 2 | B22: Building area entered | C22: {="NEC "&NECREF("220")} -> NEC 220 | E22: =IF(N(LC_TotalSF)>0,"✔ "&TEXT(LC_TotalSF,"#,##0")&" SF","⚠ Enter areas on Load Calc") -> ⚠ Enter areas on Load Calc
A23: 3 | B23: New load calculated | C23: {="NEC "&NECREF("220")} -> NEC 220 | E23: =IF(N(LC_AdjustedDemand)>0,"✔ "&TEXT(LC_AdjustedDemand,"#,##0.0")&" kVA adj. demand","— No load entered yet") -> — No load entered yet
A24: 4 | B24: Suggested service size | C24: {="NEC "&NECREF("240.6")} -> NEC 240.6 | E24: =IF(N(LC_ServiceSize)>0,"✔ "&TEXT(LC_ServiceSize,"#,##0")&" A","— pending load") -> — pending load
A25: 5 | B25: Design amps within service | C25: {="NEC "&NECREF("240.4")} -> NEC 240.4 | E25: =IF(N(LC_ServiceSize)=0,"— n/a",IF(LC_DesignAmps<=LC_ServiceSize,"✔ "&TEXT(LC_DesignAmps,"#,##0")&" A ≤ service","✘ "&TEXT(LC_DesignAmps,"#,##0")&" A exceeds service")) -> — n/a
A26: 6 | B26: Existing service spare (renovation) | C26: {="NEC "&NECREF("220.87")} -> NEC 220.87 | E26: =IF(N(LC_ExistingLoad125)=0,"— n/a (new building)",IF(LC_ExistingSpare>=0,"✔ "&TEXT(LC_ExistingSpare,"#,##0.0")&" kVA spare","✘ Existing service overloaded")) -> — n/a (new building)
A27: 7 | B27: Short-circuit AIC margin | C27: {="NEC "&NECREF("110.9")&" / "&NECREF("110.10")} -> NEC 110.9 / 110.10 | E27: =IFERROR(IF(COUNT('Short Circuit'!$S$6:$S$255)=0,IF(COUNTA(Equip_List)=0,"— no equipment yet","⚠ "&$H$13),IF(MIN('Short Circuit'!$S$6:$S$255)>=0,"✔ "&TEXT(MIN('Short Circuit'!$S$6:$S$255),"#,##0")&" A min margin ("&COUNT('Short Circuit'!$S$6:$S$255)&" buses)"&IF(COUNT('Short Circuit'!$S$6:$S$255)<(COUNTIFS('Short Circuit'!$A$6:$A$255,"?*",'Short Circuit'!$C$6:$C$255,"<>0")-COUNTIFS('Short Circuit'!$A$6:$A$255,"T-*",'Short Circuit'!$R$6:$R$255,""))," · ⚠ "&((COUNTIFS('Short Circuit'!$A$6:$A$255,"?*",'Short Circuit'!$C$6:$C$255,"<>0")-COUNTIFS('Short Circuit'!$A$6:$A$255,"T-*",'Short Circuit'!$R$6:$R$255,""))-COUNT('Short Circuit'!$S$6:$S$255))&" missing",""),"✘ AIC exceeded at "&COUNTIF('Short Circuit'!$S$6:$S$255,"<0")&" bus(es)")),"— run study") -> — no equipment yet
A28: 8 | B28: Voltage drop within limit | C28: {="NEC "&NECREF("210.19")&" / "&NECREF("215.2")&" IN"} -> NEC 210.19 / 215.2 IN | E28: =IFERROR(_xlfn.LET(_xlpm.n,COUNTIFS('Voltage Drop'!$A$6:$A$255,"?*",'Voltage Drop'!$C$6:$C$255,">0"),_xlpm.m,COUNT('Voltage Drop'!$H$6:$H$255)-COUNTIFS('Voltage Drop'!$C$6:$C$255,0),_xlpm.w,MAX('Voltage Drop'!$H$6:$H$255),IF(_xlpm.n=0,IF(COUNTA(Equip_List)=0,"— no equipment yet","— run study"),IF(_xlpm.m<=0,"⚠ Missing: feeder load / length (Feeder Schedule)",IF(_xlpm.w<=Cfg_VDTotal,"✔ "&TEXT(_xlpm.w,"0.0%")&" worst cumulative ≤ "&TEXT(Cfg_VDTotal,"0%"),"⚠ "&TEXT(_xlpm.w,"0.0%")&" worst cumulative > "&TEXT(Cfg_VDTotal,"0%"))&IF(_xlpm.m<_xlpm.n," · "&(_xlpm.n-_xlpm.m)&" bus(es) missing data","")))),"— run study") -> — no equipment yet
A29: 9 | B29: Arc-flash incident energy | C29: IEEE 1584 | E29: =IFERROR(IF(COUNT('Arc Flash'!$M$24:$M$296)=0,IF(COUNTA(Equip_List)=0,"— no equipment yet","⚠ "&$H$15),IF(MAX('Arc Flash'!$M$24:$M$296)<=40,"✔ "&TEXT(MAX('Arc Flash'!$M$24:$M$296),"0.0")&" cal/cm² worst case","✘ "&TEXT(MAX('Arc Flash'!$M$24:$M$296),"0.0")&" cal/cm² >40")),"— run study") -> — no equipment yet
A30: 10 | B30: Feeder conductor / OCPD sizing | C30: {="NEC "&NECREF("310.16")&" / "&NECREF("240.6")} -> NEC 310.16 / 240.6 | E30: =IF('Feeder Schedule'!$B$5="","— add feeders",IF(N('Feeder Schedule'!$I$5)=0,"— enter feeder load","✔ "&COUNT('Feeder Schedule'!$I$5:$I$254)&" feeder(s) · first "&'Feeder Schedule'!$P$5&" / "&TEXT('Feeder Schedule'!$R$5,"#,##0")&" A")) -> — add feeders
A31: 11 | B31: Generator sizing | C31: {="NEC "&NECREF("700")&" / 701 / 702"} -> NEC 700 / 701 / 702 | E31: =IF(Tog_Gen<>"ON",IF(N(LC_GenTotal)>0,"⚠ "&TEXT(LC_GenTotal,"#,##0.0")&" kVA tagged Gen — add Generator (ribbon)","— not in project"),IFERROR(IF(N(Generator!$D$40)=0,"⚠ "&$H$10,IF(ISNUMBER(Generator!$D$45),"✔ "&TEXT(Generator!$D$45,"#,##0")&" kW","⚠ above largest standard size")),"— n/a")) -> — not in project
A32: 12 | B32: UPS sizing | C32: Critical power | E32: =IF(Tog_UPS<>"ON",IF(N(LC_UPSTotal)>0,"⚠ "&TEXT(LC_UPSTotal,"#,##0.0")&" kVA tagged UPS — add UPS (ribbon)","— not in project"),IFERROR(IF($G$11="◐ Incomplete","⚠ "&$H$11,"✔ "&$H$11),"— n/a")) -> — not in project
A33: 13 | B33: Panel load reconciliation | C33: Dashboard § Panel Load Reconciliation | E33: =_xlfn.LET(_xlpm.f,$F$359:$F$398,_xlpm.n,COUNTIF(_xlpm.f,"OK")+COUNTIF(_xlpm.f,"CHECK")+COUNTIF(_xlpm.f,"link not set"),_xlpm.bad,COUNTIF(_xlpm.f,"CHECK"),_xlpm.uns,COUNTIF(_xlpm.f,"link not set"),IF(_xlpm.n=0,"— no panels yet",IF(_xlpm.bad>0,"✘ "&_xlpm.bad&" panel(s) mismatch",IF(_xlpm.uns>0,"⚠ "&_xlpm.uns&" panel link(s) not set","✔ "&_xlpm.n&" panels reconcile")))) -> — no panels yet
A34: 14 | B34: Load Calc loads placed on panels | C34: Load Calc ▸ Send to Panel | E34: =_xlfn.LET(_xlpm.n,SUM('Load Calc'!$AG$7:$AG$40),_xlpm.k,SUM('Load Calc'!$AH$7:$AH$40),_xlpm.p,COUNTIF('Load Calc'!$X$41:$X$601,"Placed"),IF(_xlpm.n>0,"⚠ "&_xlpm.n&" load(s) not fully placed — "&TEXT(_xlpm.k,"#,##0.0")&" kVA",IF(_xlpm.p>0,"✔ "&_xlpm.p&" load(s) placed on panels","— no loads entered"))) -> — no loads entered
A36: ELECTRICAL SYSTEM
B38: System Voltage (select)
B39: Nominal Voltage (L-L) | C39: =IFERROR(VLOOKUP($C$38,Volt_Table,2,FALSE),"")
B40: Phase | C40: =IFERROR(VLOOKUP($C$38,Volt_Table,3,FALSE),"")
B41: Wires | C41: =IFERROR(VLOOKUP($C$38,Volt_Table,4,FALSE),"")
B42: Voltage (L-N) | C42: =IFERROR(VLOOKUP($C$38,Volt_Table,5,FALSE),"")
B43: Voltage Class | C43: =IFERROR(VLOOKUP($C$38,Volt_Table,6,FALSE),"")
A45: DESIGN DEFAULTS
B47: Branch Conductor Material | C47: Cu
B48: Feeder Conductor Material | C48: Cu
...

Sheet Load Calc
A1: SERVICE LOAD CALCULATION
B2: Project: | C2: =IF(Dashboard!B7="","—",Dashboard!B7) -> — | H2: Service Voltage: | I2: =IF(Dashboard!$C$38="","",Dashboard!$C$38) | N2: Date: | O2: =IF(Dashboard!B12="",TODAY(),Dashboard!B12) -> 46322
A4: BASELINE SQUARE FOOTAGE
AA5: SECTION REGISTRY — ribbon-controlled (does not print)
AA6: Section | AB6: Table | AC6: Include | AD6: Connected kVA | AE6: Gen tag list | AF6: UPS tag list | AG6: Not placed (loads) | AH6: Not placed (kVA)
B7: Space Type | C7: SF per Floor | D7: Floors | E7: Total SF | F7: LPD (W/ft²) | G7: Lighting W | AA7: 1 Site / Exterior | AB7: LC_Site | AC7: Yes | AD7: =IF($AC7="No","n/a",SUM(LC_Site[Total kVA])) -> 0 | AE7: Y | AF7: Y | AG7: =IF($AC7="No",0,COUNTIFS(LC_Site[Status],"Unplaced")+COUNTIFS(LC_Site[Status],"Partial")) -> 0 | AH7: =IF($AC7="No",0,SUMIFS(LC_Site[Total kVA],LC_Site[Status],"Unplaced")+SUMIFS(LC_Site[Total kVA],LC_Site[Status],"Partial")) -> 0
E8: =IF(OR(LC_Areas[[#This Row],[SF per Floor]]="",LC_Areas[[#This Row],[Floors]]=""),"",LC_Areas[[#This Row],[SF per Floor]]*LC_Areas[[#This Row],[Floors]]) | F8: =IF(LC_Areas[[#This Row],[Space Type]]="","",_xlfn.LET(_xlpm.k,IF(Cfg_Energy_Code="SEC (Seattle)",3,2),_xlpm.v,IFERROR(VLOOKUP(LC_Areas[[#This Row],[Space Type]],LPD_BldgArea_Table,_xlpm.k,FALSE),IFERROR(VLOOKUP(LC_Areas[[#This Row],[Space Type]],LPD_Space_Table,_xlpm.k,FALSE),"")),IF(_xlpm.v="","not listed in "&Cfg_Energy_Code,_xlpm.v))) | G8: =IF(OR(LC_Areas[[#This Row],[Total SF]]="",NOT(ISNUMBER(LC_Areas[[#This Row],[LPD (W/ft²)]]))),"",LC_Areas[[#This Row],[Total SF]]*LC_Areas[[#This Row],[LPD (W/ft²)]]) | AA8: 2 House / Misc | AB8: LC_House | AC8: Yes | AD8: =IF($AC8="No","n/a",SUM(LC_House[Total kVA])) -> 0 | AE8: =IF(Generator!$B$53="","",Generator!$B$53) -> GEN-1 | AF8: =IF(UPS!$B$48="","",UPS!$B$48) -> UPS-1 | AG8: =IF($AC8="No",0,COUNTIFS(LC_House[Status],"Unplaced")+COUNTIFS(LC_House[Status],"Partial")) -> 0 | AH8: =IF($AC8="No",0,SUMIFS(LC_House[Total kVA],LC_House[Status],"Unplaced")+SUMIFS(LC_House[Total kVA],LC_House[Status],"Partial")) -> 0
B9: TOTAL BUILDING SF | E9: =SUM(LC_Areas[Total SF]) -> 0 | F9: =IF(N(E9)=0,"",G9/E9) | G9: =SUM(LC_Areas[Lighting W]) -> 0 | AA9: 3 Department / Owner | AB9: LC_Dept | AC9: Yes | AD9: =IF($AC9="No","n/a",SUM(LC_Dept[Total kVA])) -> 0 | AE9: =IF(Generator!$B$54="","",Generator!$B$54) | AF9: =IF(UPS!$B$49="","",UPS!$B$49) | AG9: =IF($AC9="No",0,COUNTIFS(LC_Dept[Status],"Unplaced")+COUNTIFS(LC_Dept[Status],"Partial")) -> 0 | AH9: =IF($AC9="No",0,SUMIFS(LC_Dept[Total kVA],LC_Dept[Status],"Unplaced")+SUMIFS(LC_Dept[Total kVA],LC_Dept[Status],"Partial")) -> 0
AA10: 4 Refrigeration (optional) | AB10: LC_Refrig | AC10: No | AD10: =IF($AC10="No","n/a",SUM(LC_Refrig[Total kVA])) -> n/a | AE10: =IF(Generator!$B$55="","",Generator!$B$55) | AF10: =IF(UPS!$B$50="","",UPS!$B$50) | AG10: =IF($AC10="No",0,COUNTIFS(LC_Refrig[Status],"Unplaced")+COUNTIFS(LC_Refrig[Status],"Partial")) -> 0 | AH10: =IF($AC10="No",0,SUMIFS(LC_Refrig[Total kVA],LC_Refrig[Status],"Unplaced")+SUMIFS(LC_Refrig[Total kVA],LC_Refrig[Status],"Partial")) -> 0
A11: ="LIGHTING POWER DENSITY — "&LEFT(Cfg_Energy_Code,FIND(" ",Cfg_Energy_Code&" ")-1)&" C405.4.2" -> LIGHTING POWER DENSITY — C405.4.2 | AA11: 5 Mechanical | AB11: LC_Mech | AC11: Yes | AD11: =IF($AC11="No","n/a",SUM(LC_Mech[Total kVA])) -> 0 | AG11: =IF($AC11="No",0,COUNTIFS(LC_Mech[Status],"Unplaced")+COUNTIFS(LC_Mech[Status],"Partial")) -> 0 | AH11: =IF($AC11="No",0,SUMIFS(LC_Mech[Total kVA],LC_Mech[Status],"Unplaced")+SUMIFS(LC_Mech[Total kVA],LC_Mech[Status],"Partial")) -> 0
AA12: 6 Plumbing | AB12: LC_Plumb | AC12: Yes | AD12: =IF($AC12="No","n/a",SUM(LC_Plumb[Total kVA])) -> 0 | AE12: =IF(Generator!$B$56="","",Generator!$B$56) | AF12: =IF(UPS!$B$51="","",UPS!$B$51) | AG12: =IF($AC12="No",0,COUNTIFS(LC_Plumb[Status],"Unplaced")+COUNTIFS(LC_Plumb[Status],"Partial")) -> 0 | AH12: =IF($AC12="No",0,SUMIFS(LC_Plumb[Total kVA],LC_Plumb[Status],"Unplaced")+SUMIFS(LC_Plumb[Total kVA],LC_Plumb[Status],"Partial")) -> 0
AA13: 7 Kitchen / Food Service (optional) | AB13: LC_Kitchen | AC13: No | AD13: =IF($AC13="No","n/a",SUM(LC_Kitchen[Total kVA])) -> n/a | AE13: =IF(Generator!$B$57="","",Generator!$B$57) | AF13: =IF(UPS!$B$52="","",UPS!$B$52) | AG13: =IF($AC13="No",0,COUNTIFS(LC_Kitchen[Status],"Unplaced")+COUNTIFS(LC_Kitchen[Status],"Partial")) -> 0 | AH13: =IF($AC13="No",0,SUMIFS(LC_Kitchen[Total kVA],LC_Kitchen[Status],"Unplaced")+SUMIFS(LC_Kitchen[Total kVA],LC_Kitchen[Status],"Partial")) -> 0
B14: Energy Code (Jurisdiction) | AA14: 8 Elevators / Conveying (optional) | AB14: LC_Elev | AC14: No | AD14: =IF($AC14="No","n/a",SUM(LC_Elev[Total kVA])) -> n/a | AE14: =IF(Generator!$B$58="","",Generator!$B$58) | AF14: =IF(UPS!$B$53="","",UPS!$B$53) | AG14: =IF($AC14="No",0,COUNTIFS(LC_Elev[Status],"Unplaced")+COUNTIFS(LC_Elev[Status],"Partial")) -> 0 | AH14: =IF($AC14="No",0,SUMIFS(LC_Elev[Total kVA],LC_Elev[Status],"Unplaced")+SUMIFS(LC_Elev[Total kVA],LC_Elev[Status],"Partial")) -> 0
B15: Compliance Method | AA15: 9 EV Charging (optional) | AB15: LC_EV | AC15: No | AD15: =IF($AC15="No","n/a",SUM(LC_EV[Total kVA])) -> n/a | AG15: =IF($AC15="No",0,COUNTIFS(LC_EV[Status],"Unplaced")+COUNTIFS(LC_EV[Status],"Partial")) -> 0 | AH15: =IF($AC15="No",0,SUMIFS(LC_EV[Total kVA],LC_EV[Status],"Unplaced")+SUMIFS(LC_EV[Total kVA],LC_EV[Status],"Partial")) -> 0
B16: Total Lighting Watts (from SF table) | C16: =SUM(LC_Areas[Lighting W]) -> 0 | AA16: 10 Data / IT | AB16: LC_Data | AC16: Yes | AD16: =IF($AC16="No","n/a",SUM(LC_Data[Total kVA])) -> 0 | AG16: =IF($AC16="No",0,COUNTIFS(LC_Data[Status],"Unplaced")+COUNTIFS(LC_Data[Status],"Partial")) -> 0 | AH16: =IF($AC16="No",0,SUMIFS(LC_Data[Total kVA],LC_Data[Status],"Unplaced")+SUMIFS(LC_Data[Total kVA],LC_Data[Status],"Partial")) -> 0
B17: Total Building SF | C17: =SUM(LC_Areas[Total SF]) -> 0 | AA17: 11 Fire / Life Safety (optional) | AB17: LC_Fire | AC17: No | AD17: =IF($AC17="No","n/a",SUM(LC_Fire[Total kVA])) -> n/a | AG17: =IF($AC17="No",0,COUNTIFS(LC_Fire[Status],"Unplaced")+COUNTIFS(LC_Fire[Status],"Partial")) -> 0 | AH17: =IF($AC17="No",0,SUMIFS(LC_Fire[Total kVA],LC_Fire[Status],"Unplaced")+SUMIFS(LC_Fire[Total kVA],LC_Fire[Status],"Partial")) -> 0
B18: GOVERNING BLENDED LPD (W/ft²) | C18: =IF(N($C$17)=0,0,$C$16/$C$17) -> 0 | AA18: 12 Process / Industrial (optional) | AB18: LC_Process | AC18: No | AD18: =IF($AC18="No","n/a",SUM(LC_Process[Total kVA])) -> n/a | AG18: =IF($AC18="No",0,COUNTIFS(LC_Process[Status],"Unplaced")+COUNTIFS(LC_Process[Status],"Partial")) -> 0 | AH18: =IF($AC18="No",0,SUMIFS(LC_Process[Total kVA],LC_Process[Status],"Unplaced")+SUMIFS(LC_Process[Total kVA],LC_Process[Status],"Partial")) -> 0
B19: Lighting Type Completeness | C19: =_xlfn.LET(_xlpm.n,COUNTIFS(LC_Areas[Total SF],">0"),_xlpm.m,COUNTIFS(LC_Areas[Total SF],">0",LC_Areas[Space Type],""),_xlpm.x,COUNTIF(LC_Areas[LPD (W/ft²)],"not listed*"),IF(_xlpm.n=0,"— no areas entered",IF(_xlpm.x>0,"✘ "&_xlpm.x&" type(s) not listed in "&Cfg_Energy_Code,IF(_xlpm.m>0,"⚠ "&_xlpm.m&" of "&_xlpm.n&" area(s) missing a type","✔ all "&_xlpm.n&" area(s) typed")))) -> — no areas entered
A21: GENERAL DEMAND ALLOWANCES (W/SF)
B24: Category | C24: W/SF | D24: Applies to SF | E24: Connected kVA | F24: Demand Factor | G24: Demand kVA
B25: General Power | C25: 2 | D25: =SUM(LC_Areas[Total SF]) -> 0 | E25: =IF(OR(LC_WSF[[#This Row],[W/SF]]="",LC_WSF[[#This Row],[Applies to SF]]=""),"",LC_WSF[[#This Row],[W/SF]]*LC_WSF[[#This Row],[Applies to SF]]/1000) -> 0 | F25: =IF(OR(E25="",E25=0),"",(MIN(E25*1000,Rcpt_Thresh_VA)+MAX(0,E25*1000-Rcpt_Thresh_VA)*Rcpt_Rem_DF)/1000/E25) | G25: =IF(LC_WSF[[#This Row],[Connected kVA]]="","",LC_WSF[[#This Row],[Connected kVA]]*IF(LC_WSF[[#This Row],[Demand Factor]]="",1,LC_WSF[[#This Row],[Demand Factor]])) -> 0
B26: Computer Power | C26: 2 | D26: =SUM(LC_Areas[Total SF]) -> 0 | E26: =IF(OR(LC_WSF[[#This Row],[W/SF]]="",LC_WSF[[#This Row],[Applies to SF]]=""),"",LC_WSF[[#This Row],[W/SF]]*LC_WSF[[#This Row],[Applies to SF]]/1000) -> 0 | F26: 1 | G26: =IF(LC_WSF[[#This Row],[Connected kVA]]="","",LC_WSF[[#This Row],[Connected kVA]]*IF(LC_WSF[[#This Row],[Demand Factor]]="",1,LC_WSF[[#This Row],[Demand Factor]])) -> 0
B27: ="General Lighting ("&LEFT(Cfg_Energy_Code,FIND(" ",Cfg_Energy_Code&" ")-1)&" C405.4.2)" -> General Lighting ( C405.4.2) | C27: =$C$18 -> 0 | D27: =SUM(LC_Areas[Total SF]) -> 0 | E27: =IF(OR(LC_WSF[[#This Row],[W/SF]]="",LC_WSF[[#This Row],[Applies to SF]]=""),"",LC_WSF[[#This Row],[W/SF]]*LC_WSF[[#This Row],[Applies to SF]]/1000) -> 0 | F27: 1 | G27: =IF(LC_WSF[[#This Row],[Connected kVA]]="","",LC_WSF[[#This Row],[Connected kVA]]*IF(LC_WSF[[#This Row],[Demand Factor]]="",1,LC_WSF[[#This Row],[Demand Factor]])) -> 0
B28: General Mechanical & Plumbing | C28: 15 | D28: =SUM(LC_Areas[Total SF]) -> 0 | E28: =IF(OR(LC_WSF[[#This Row],[W/SF]]="",LC_WSF[[#This Row],[Applies to SF]]=""),"",LC_WSF[[#This Row],[W/SF]]*LC_WSF[[#This Row],[Applies to SF]]/1000) -> 0 | F28: 1 | G28: =IF(LC_WSF[[#This Row],[Connected kVA]]="","",LC_WSF[[#This Row],[Connected kVA]]*IF(LC_WSF[[#This Row],[Demand Factor]]="",1,LC_WSF[[#This Row],[Demand Factor]])) -> 0
B29: TOTAL W/SF LOADS | E29: =SUM(LC_WSF[Connected kVA]) -> 0 | G29: =SUM(LC_WSF[Demand kVA]) -> 0
A31: {="EXISTING BUILDING DEMAND — NEC "&NECREF("220.87")&" (12-MONTH BILLS OR 30-DAY LOGGING)"} -> EXISTING BUILDING DEMAND — NEC 220.87 (12-MONTH BILLS OR 30-DAY LOGGING)
B34: Peak Existing Demand (kW) | C34: =IF($G$34="30-Day Metered Logging",'Logging Demand'!$C$45,'Utility Demand'!$G$36) -> 0 | F34: {="Method (NEC "&NECREF("220.87")&")"} -> Method (NEC 220.87)
B35: Peak Demand (kVA) | C35: =IF($G$34="30-Day Metered Logging",'Logging Demand'!$C$47,'Utility Demand'!$G$37) -> 0 | F35: Existing Service Size (A)
B36: {="NEC "&NECREF("220.87")&" Existing Load = 125% × Peak (kVA)"} -> NEC 220.87 Existing Load = 125% × Peak (kVA) | C36: =IF($C$35="","",1.25*$C$35) -> 0 | F36: Existing Service Capacity (kVA) | G36: =IF(OR($G$35="",NOT(ISNUMBER(Cfg_Volt))),"",$G$35*Cfg_Volt*IF(Cfg_Phase=3,SQRT3,1)/1000)
B37: Spare Capacity on Existing Service (kVA) | C37: =IF(OR($C$36="",$G$36=""),"",$G$36-$C$36) | F37: Service Utilization (%) | G37: =IF(OR($C$36="",$G$36=""),"",$C$36/$G$36)
B38: {=IF(NEC_Ed="NEC 2026","Load Being Removed (kVA) — NEC "&NECREF("220.87")&"(2)","Load Being Removed (kVA) — used only with NEC 2026")} -> Load Being Removed (kVA) — used only with NEC 2026
B39: {="Auto-filled from the NEC "&NECREF("220.87")&" module chosen at right — 12-Month Utility Bills (Utility Demand tab) or 30-Day Metered Logging (Logging Demand tab). Enter the source data on that tab; only the selected method feeds this total."} -> Auto-filled from the NEC 220.87 module chosen at right — 12-Month Utility Bills (Utility Demand tab) or 30-Day Metered Logging (Logging Demand tab). Enter the source data on that tab; only the selected method feeds this total.
A41: SITE / EXTERIOR
A43: No. | B43: Description | C43: Qty | D43: Connection | E43: Disc NEMA | F43: Disc Frame (A) | G43: Disc Fuse (A) | H43: Disc Supplied By | I43: Recept Type | J43: Load Value | K43: Unit | L43: Volts | M43: Ph | N43: PF | O43: kVA Each | P43: Total kVA | Q43: Ded. Ckt | R43: Gen | S43: UPS | T43: Panel Tag | U43: Notes | V43: Ckts | W43: Placed | X43: Status
O44: {=IF(OR(LC_Site[[#This Row],[Qty]]="",LC_Site[[#This Row],[Load Value]]="",LC_Site[[#This Row],[Unit]]=""),"",IFERROR(_xlfn.SWITCH(LC_Site[[#This Row],[Unit]],"HP",IF(LC_Site[[#This Row],[Ph]]=3,VLOOKUP(LC_Site[[#This Row],[Load Value]],Motor3_Table,IF(LC_Site[[#This Row],[Volts]]<=215,2,IF(LC_Site[[#This Row],[Volts]]<=245,3,IF(LC_Site[[#This Row],[Volts]]<=500,4,5))),TRUE)*LC_Site[[#This Row],[Volts]]*SQRT3/1000,VLOOKUP(LC_Site[[#This Row],[Load Value]],Motor1_Table,IF(LC_Site[[#This Row],[Volts]]<=130,2,3),TRUE)*LC_Site[[#This Row],[Volts]]/1000),"kW",LC_Site[[#This Row],[Load Value]]/IF(LC_Site[[#This Row],[PF]]="",0.9,LC_Site[[#This Row],[PF]]),"kVA",LC_Site[[#This Row],[Load Value]],"A",LC_Site[[#This Row],[Load Value]]*LC_Site[[#This Row],[Volts]]*IF(LC_Site[[#This Row],[Ph]]=3,SQRT3,1)/1000,"W",LC_Site[[#This Row],[Load Value]]/IF(LC_Site[[#This Row],[PF]]="",0.9,LC_Site[[#This Row],[PF]])/1000,"VA",LC_Site[[#This Row],[Load Value]]/1000),"chk"))} | P44: =IF(NOT(ISNUMBER(LC_Site[[#This Row],[kVA Each]])),"",LC_Site[[#This Row],[Qty]]*LC_Site[[#This Row],[kVA Each]]) | W44: 0 | X44: =IF(LC_Site[[#This Row],[Description]]="","",IF(N(LC_Site[[#This Row],[Placed]])=0,"Unplaced",IF(LC_Site[[#This Row],[Placed]]>=IF(LC_Site[[#This Row],[Ded. Ckt]]="N",1,MAX(1,N(LC_Site[[#This Row],[Qty]]))),"Placed","Partial")))
B46: NEC DEMAND FACTOR × SECTION TOTAL = SECTION DEMAND → | G46: 1 | O46: =SUM(LC_Site[Total kVA]) -> 0 | P46: =ROUND(IFERROR($O46*$G46,0),1) -> 0
A48: HOUSE / MISCELLANEOUS EQUIPMENT
A50: No. | B50: Description | C50: Qty | D50: Connection | E50: Disc NEMA | F50: Disc Frame (A) | G50: Disc Fuse (A) | H50: Disc Supplied By | I50: Recept Type | J50: Load Value | K50: Unit | L50: Volts | M50: Ph | N50: PF | O50: kVA Each | P50: Total kVA | Q50: Ded. Ckt | R50: Gen | S50: UPS | T50: Panel Tag | U50: Notes | V50: Ckts | W50: Placed | X50: Status
O51: {=IF(OR(LC_House[[#This Row],[Qty]]="",LC_House[[#This Row],[Load Value]]="",LC_House[[#This Row],[Unit]]=""),"",IFERROR(_xlfn.SWITCH(LC_House[[#This Row],[Unit]],"HP",IF(LC_House[[#This Row],[Ph]]=3,VLOOKUP(LC_House[[#This Row],[Load Value]],Motor3_Table,IF(LC_House[[#This Row],[Volts]]<=215,2,IF(LC_House[[#This Row],[Volts]]<=245,3,IF(LC_House[[#This Row],[Volts]]<=500,4,5))),TRUE)*LC_House[[#This Row],[Volts]]*SQRT3/1000,VLOOKUP(LC_House[[#This Row],[Load Value]],Motor1_Table,IF(LC_House[[#This Row],[Volts]]<=130,2,3),TRUE)*LC_House[[#This Row],[Volts]]/1000),"kW",LC_House[[#This Row],[Load Value]]/IF(LC_House[[#This Row],[PF]]="",0.9,LC_House[[#This Row],[PF]]),"kVA",LC_House[[#This Row],[Load Value]],"A",LC_House[[#This Row],[Load Value]]*LC_House[[#This Row],[Volts]]*IF(LC_House[[#This Row],[Ph]]=3,SQRT3,1)/1000,"W",LC_House[[#This Row],[Load Value]]/IF(LC_House[[#This Row],[PF]]="",0.9,LC_House[[#This Row],[PF]])/1000,"VA",LC_House[[#This Row],[Load Value]]/1000),"chk"))} | P51: =IF(NOT(ISNUMBER(LC_House[[#This Row],[kVA Each]])),"",LC_House[[#This Row],[Qty]]*LC_House[[#This Row],[kVA Each]]) | W51: 0 | X51: =IF(LC_House[[#This Row],[Description]]="","",IF(N(LC_House[[#This Row],[Placed]])=0,"Unplaced",IF(LC_House[[#This Row],[Placed]]>=IF(LC_House[[#This Row],[Ded. Ckt]]="N",1,MAX(1,N(LC_House[[#This Row],[Qty]]))),"Placed","Partial")))
B53: NEC DEMAND FACTOR × SECTION TOTAL = SECTION DEMAND → | G53: 1 | O53: =SUM(LC_House[Total kVA]) -> 0 | P53: =ROUND(IFERROR($O53*$G53,0),1) -> 0
...

Sheet Utility Demand
A1: {="UTILITY DEMAND ANALYSIS — NEC "&NECREF("220.87")&"(1) — 12-MONTH BILLING DATA"} -> UTILITY DEMAND ANALYSIS — NEC 220.87(1) — 12-MONTH BILLING DATA
B2: Project: | C2: =IF(Dashboard!B7="","—",Dashboard!B7) -> — | G2: Service Voltage: | H2: =IF(Dashboard!$C$38="","",Dashboard!$C$38)
A4: SETTINGS
C6: Default Power Factor | D6: 0.9 | E6: Used only when a bill has neither kVAR nor a stated PF.
C7: Assumed Load Factor (optional) | E7: If a bill has no metered peak, Peak kW = Avg kW ÷ Load Factor. Leave blank to use metered peaks only.
C8: System Voltage (L-L) | D8: =Dashboard!C39
C9: Phase | D9: =Dashboard!C40
C10: Existing Service (A) | E10: Main breaker / service rating. Leave blank for a new service; capacity in D11 stays blank.
C11: Existing Service Capacity (kVA) | D11: =IF(OR(D10=0,D10="",D8="",D9=""),"",IF(D9=3,D8*D10*SQRT(3)/1000,D8*D10/1000))
A13: METER 1 | L13: SÄZÄN PowerCalc ▸ Existing Demand ▸ Add Meter creates another meter section below.
B15: Meter # | E15: Source: | H15: Rate Schedule: | K15: Serves:
E16: Utility: | F16: =_xlfn.LET(_xlpm.t,""&$F15,_xlpm.p,IF(_xlpm.t="",INDEX(Util_Provider,1),_xlfn.XLOOKUP(_xlpm.t,Util_Tags,Util_Provider,"")),IF(""&_xlpm.p="","",_xlpm.p)) | K16: Metered Board: | M16: Board this meter measures — its 125% load lands on that board and rolls up the tree. Blank = service board.
B18: Cycle | C18: Start Date | D18: End Date | E18: Days | F18: kWh | G18: Avg kW | H18: Peak kW (Bill) | I18: Peak kVAR (Bill) | J18: PF (Bill) | K18: PF Used | L18: Peak kW Used | M18: Peak kVA | N18: Peak A | O18: Notes
B19: 1 | E19: =IF(OR($C19="",$D19=""),"",$D19-$C19) | G19: =IF(OR($F19="",$E19=""),"",$F19/($E19*24)) | K19: =IF($J19<>"",$J19,IF(AND($H19<>"",$I19<>""),$H19/SQRT($H19^2+$I19^2),$D$6)) -> 0.9 | L19: =IF($H19<>"",$H19,IF(AND($G19<>"",$D$7<>""),$G19/$D$7,"")) | M19: =IF($L19="","",$L19/$K19) | N19: =IF(OR($M19="",N($D$8)=0),"",$M19*1000/IF($D$9=3,$D$8*SQRT(3),$D$8))
B20: 2 | E20: =IF(OR($C20="",$D20=""),"",$D20-$C20) | G20: =IF(OR($F20="",$E20=""),"",$F20/($E20*24)) | K20: =IF($J20<>"",$J20,IF(AND($H20<>"",$I20<>""),$H20/SQRT($H20^2+$I20^2),$D$6)) -> 0.9 | L20: =IF($H20<>"",$H20,IF(AND($G20<>"",$D$7<>""),$G20/$D$7,"")) | M20: =IF($L20="","",$L20/$K20) | N20: =IF(OR($M20="",N($D$8)=0),"",$M20*1000/IF($D$9=3,$D$8*SQRT(3),$D$8))
B21: 3 | E21: =IF(OR($C21="",$D21=""),"",$D21-$C21) | G21: =IF(OR($F21="",$E21=""),"",$F21/($E21*24)) | K21: =IF($J21<>"",$J21,IF(AND($H21<>"",$I21<>""),$H21/SQRT($H21^2+$I21^2),$D$6)) -> 0.9 | L21: =IF($H21<>"",$H21,IF(AND($G21<>"",$D$7<>""),$G21/$D$7,"")) | M21: =IF($L21="","",$L21/$K21) | N21: =IF(OR($M21="",N($D$8)=0),"",$M21*1000/IF($D$9=3,$D$8*SQRT(3),$D$8))
B22: 4 | E22: =IF(OR($C22="",$D22=""),"",$D22-$C22) | G22: =IF(OR($F22="",$E22=""),"",$F22/($E22*24)) | K22: =IF($J22<>"",$J22,IF(AND($H22<>"",$I22<>""),$H22/SQRT($H22^2+$I22^2),$D$6)) -> 0.9 | L22: =IF($H22<>"",$H22,IF(AND($G22<>"",$D$7<>""),$G22/$D$7,"")) | M22: =IF($L22="","",$L22/$K22) | N22: =IF(OR($M22="",N($D$8)=0),"",$M22*1000/IF($D$9=3,$D$8*SQRT(3),$D$8))
B23: 5 | E23: =IF(OR($C23="",$D23=""),"",$D23-$C23) | G23: =IF(OR($F23="",$E23=""),"",$F23/($E23*24)) | K23: =IF($J23<>"",$J23,IF(AND($H23<>"",$I23<>""),$H23/SQRT($H23^2+$I23^2),$D$6)) -> 0.9 | L23: =IF($H23<>"",$H23,IF(AND($G23<>"",$D$7<>""),$G23/$D$7,"")) | M23: =IF($L23="","",$L23/$K23) | N23: =IF(OR($M23="",N($D$8)=0),"",$M23*1000/IF($D$9=3,$D$8*SQRT(3),$D$8))
B24: 6 | E24: =IF(OR($C24="",$D24=""),"",$D24-$C24) | G24: =IF(OR($F24="",$E24=""),"",$F24/($E24*24)) | K24: =IF($J24<>"",$J24,IF(AND($H24<>"",$I24<>""),$H24/SQRT($H24^2+$I24^2),$D$6)) -> 0.9 | L24: =IF($H24<>"",$H24,IF(AND($G24<>"",$D$7<>""),$G24/$D$7,"")) | M24: =IF($L24="","",$L24/$K24) | N24: =IF(OR($M24="",N($D$8)=0),"",$M24*1000/IF($D$9=3,$D$8*SQRT(3),$D$8))
B25: 7 | E25: =IF(OR($C25="",$D25=""),"",$D25-$C25) | G25: =IF(OR($F25="",$E25=""),"",$F25/($E25*24)) | K25: =IF($J25<>"",$J25,IF(AND($H25<>"",$I25<>""),$H25/SQRT($H25^2+$I25^2),$D$6)) -> 0.9 | L25: =IF($H25<>"",$H25,IF(AND($G25<>"",$D$7<>""),$G25/$D$7,"")) | M25: =IF($L25="","",$L25/$K25) | N25: =IF(OR($M25="",N($D$8)=0),"",$M25*1000/IF($D$9=3,$D$8*SQRT(3),$D$8))
B26: 8 | E26: =IF(OR($C26="",$D26=""),"",$D26-$C26) | G26: =IF(OR($F26="",$E26=""),"",$F26/($E26*24)) | K26: =IF($J26<>"",$J26,IF(AND($H26<>"",$I26<>""),$H26/SQRT($H26^2+$I26^2),$D$6)) -> 0.9 | L26: =IF($H26<>"",$H26,IF(AND($G26<>"",$D$7<>""),$G26/$D$7,"")) | M26: =IF($L26="","",$L26/$K26) | N26: =IF(OR($M26="",N($D$8)=0),"",$M26*1000/IF($D$9=3,$D$8*SQRT(3),$D$8))
B27: 9 | E27: =IF(OR($C27="",$D27=""),"",$D27-$C27) | G27: =IF(OR($F27="",$E27=""),"",$F27/($E27*24)) | K27: =IF($J27<>"",$J27,IF(AND($H27<>"",$I27<>""),$H27/SQRT($H27^2+$I27^2),$D$6)) -> 0.9 | L27: =IF($H27<>"",$H27,IF(AND($G27<>"",$D$7<>""),$G27/$D$7,"")) | M27: =IF($L27="","",$L27/$K27) | N27: =IF(OR($M27="",N($D$8)=0),"",$M27*1000/IF($D$9=3,$D$8*SQRT(3),$D$8))
B28: 10 | E28: =IF(OR($C28="",$D28=""),"",$D28-$C28) | G28: =IF(OR($F28="",$E28=""),"",$F28/($E28*24)) | K28: =IF($J28<>"",$J28,IF(AND($H28<>"",$I28<>""),$H28/SQRT($H28^2+$I28^2),$D$6)) -> 0.9 | L28: =IF($H28<>"",$H28,IF(AND($G28<>"",$D$7<>""),$G28/$D$7,"")) | M28: =IF($L28="","",$L28/$K28) | N28: =IF(OR($M28="",N($D$8)=0),"",$M28*1000/IF($D$9=3,$D$8*SQRT(3),$D$8))
B29: 11 | E29: =IF(OR($C29="",$D29=""),"",$D29-$C29) | G29: =IF(OR($F29="",$E29=""),"",$F29/($E29*24)) | K29: =IF($J29<>"",$J29,IF(AND($H29<>"",$I29<>""),$H29/SQRT($H29^2+$I29^2),$D$6)) -> 0.9 | L29: =IF($H29<>"",$H29,IF(AND($G29<>"",$D$7<>""),$G29/$D$7,"")) | M29: =IF($L29="","",$L29/$K29) | N29: =IF(OR($M29="",N($D$8)=0),"",$M29*1000/IF($D$9=3,$D$8*SQRT(3),$D$8))
B30: 12 | E30: =IF(OR($C30="",$D30=""),"",$D30-$C30) | G30: =IF(OR($F30="",$E30=""),"",$F30/($E30*24)) | K30: =IF($J30<>"",$J30,IF(AND($H30<>"",$I30<>""),$H30/SQRT($H30^2+$I30^2),$D$6)) -> 0.9 | L30: =IF($H30<>"",$H30,IF(AND($G30<>"",$D$7<>""),$G30/$D$7,"")) | M30: =IF($L30="","",$L30/$K30) | N30: =IF(OR($M30="",N($D$8)=0),"",$M30*1000/IF($D$9=3,$D$8*SQRT(3),$D$8))
B31: METER PEAK | C31: =IF($C$15="","(enter meter #)","Meter "&$C$15) -> (enter meter #) | E31: Bill-year kWh → | F31: =SUM(F19:F30) -> 0 | K31: Peak → | L31: =IFERROR(MAX(L19:L30),0) -> 0 | M31: =IFERROR(MAX(M19:M30),0) -> 0 | N31: =IFERROR(MAX(N19:N30),0) -> 0 | O31: {=IF(TRIM(L16&"")<>"",TRIM(L16&""),Exist_ServiceBoard)}
A33: {="RESULTS — NEC "&NECREF("220.87")&" EXISTING LOAD (ALL METERS)"} -> RESULTS — NEC 220.87 EXISTING LOAD (ALL METERS)
F35: Meters Included | G35: =COUNTIF($B:$B,"METER PEAK") -> 1
F36: Total Existing Peak Demand — Sum of Meter Peaks (kW) | G36: =SUMIF($B:$B,"METER PEAK",$L:$L) -> 0
F37: Total Existing Peak Demand (kVA) | G37: =SUMIF($B:$B,"METER PEAK",$M:$M) -> 0
F38: Total Existing Peak Demand (A) | G38: =SUMIF($B:$B,"METER PEAK",$N:$N) -> 0
F39: {="NEC "&NECREF("220.87")&" Existing Load = 125% × Peak (kVA)"} -> NEC 220.87 Existing Load = 125% × Peak (kVA) | G39: =G37*1.25 -> 0
F40: {="NEC "&NECREF("220.87")&" Existing Load (A)"} -> NEC 220.87 Existing Load (A) | G40: =G38*1.25 -> 0
F41: Existing Service Capacity (kVA) | G41: =IF(D11="","",D11)
F42: Spare Capacity for New Load (kVA) | G42: =IF(G41="","",G41-G39)
F43: Service Utilization (%) | G43: =IF(G41="","",G39/G41)
B45: {="NEC "&NECREF("220.87")&"(1): existing load basis requires demand data for a full year (12 consecutive billing cycles). Multi-meter total is the non-coincident sum of each meter's individual peak (conservative)."} -> NEC 220.87(1): existing load basis requires demand data for a full year (12 consecutive billing cycles). Multi-meter total is the non-coincident sum of each meter's individual peak (conservative).
B46: PF per bill: enter the billed PF directly, or enter Peak kVAR and PF is derived (kW/√(kW²+kVAR²)). Bills with PF below 0.90 flag gold.
A48: PEAK DEMAND PROFILE — BY BILLING CYCLE (ALL METERS)
B50: Cycle | C50: Month | D50: Peak kVA | E50: Peak Cycle | F50: 125% Mark (kVA)
...

Sheet Logging Demand
A1: {="30-DAY LOGGING DEMAND — NEC "&NECREF("220.87")&"(2) — METERING / LOGGING SESSION"} -> 30-DAY LOGGING DEMAND — NEC 220.87(2) — METERING / LOGGING SESSION
B2: Project: | C2: =IF(Dashboard!B7="","—",Dashboard!B7) -> — | G2: Service Voltage: | H2: =IF(Dashboard!$C$38="","",Dashboard!$C$38)
A4: SETTINGS
B6: Data Source | D6: Choose whether results use the logger-reported peaks (manual block) or the raw interval data pasted below.
B7: Default Power Factor | C7: 0.9 | D7: Used when the logger provides kW only (no kVAR / PF / kVA).
B8: System Voltage (L-L) | C8: =Dashboard!C39
B9: Phase | C9: =Dashboard!C40
B10: Existing Service (A) | C10: 0
B11: Existing Service Capacity (kVA) | C11: =IF(C10=0,"",IF(C9=3,C8*C10*SQRT(3)/1000,C8*C10/1000))
B12: Service Source | D12: Dashboard utility source this logging session measured. Blank = Source 1.
B13: Utility / Provider | C13: =_xlfn.LET(_xlpm.t,""&$C12,_xlpm.p,IF(_xlpm.t="",INDEX(Util_Provider,1),_xlfn.XLOOKUP(_xlpm.t,Util_Tags,Util_Provider,"")),IF(""&_xlpm.p="","",_xlpm.p)) | D13: From Dashboard ▸ Utility Sources — enter the provider there.
B14: Metered Board | D14: {="Board this session measured — its NEC "&NECREF("220.87")&" load lands on "&IF(Exist_LogBoard="","(no board yet)",Exist_LogBoard)&" and rolls up the tree. Blank = service board."} -> Board this session measured — its NEC 220.87 load lands on (no board yet) and rolls up the tree. Blank = service board.
A15: MANUAL PEAK ENTRY — FROM LOGGER REPORT
B17: Recording Start Date
B18: Recording End Date
B19: Recording Duration (days) | C19: =IF(OR(C17="",C18=""),"",C18-C17) | E19: {=IF(C19="","",IF(C19<30,("⚠ NEC "&NECREF("220.87")&"(2) requires a minimum 30-day recording"),"✓ ≥ 30 days"))}
B20: Recorded Peak kW
B21: Recorded Peak kVAR (optional)
B22: Recorded PF (optional)
B23: PF Used | C23: =IF(C22<>"",C22,IF(AND(C20<>"",C21<>""),C20/SQRT(C20^2+C21^2),C7)) -> 0.9
B24: Peak kVA (manual entry) | C24: =IF(C20="","",C20/C23)
A26: RAW INTERVAL DATA — SUMMARY | E26: Paste the logger export exactly as received into the grey columns G to K starting at row 54 — Date, Time, Avg kW, and kVAR / kVA if the logger supplied them. The Date column only needs a value where the day changes; blanks are carried down automatically. Columns B to E derive the timestamp and are locked. Depth is 10,000 intervals, enough for 30 days at 4-minute resolution.
B28: Records Found | C28: =COUNT($C$79:$C$50031) -> 0 | E28: =IF($C$28=0,"",IF(OR($C$31="",$C$32="",$C$32=0),"",_xlfn.LET(_xlpm.exp,ROUND($C$31*1440/$C$32,0)+1,IF(ABS(_xlpm.exp-$C$28)<=1,"✔ no gaps detected","⚠ "&TEXT(_xlpm.exp-$C$28,"#,##0")&" interval(s) missing — logger gap or partial days"))))
B29: First Timestamp | C29: =IF($C$28=0,"",MIN($B$79:$B$50031))
B30: Last Timestamp | C30: =IF($C$28=0,"",MAX($B$79:$B$50031))
B31: Recording Span (days) | C31: =IF($C$28=0,"",C30-C29) | E31: {=IF($C$31="","",IF($C$31>=30,("✔ meets the 30-day minimum in "&NECREF("220.87")),"✘ only "&TEXT($C$31,"0.0")&(" days — "&NECREF("220.87")&" requires at least 30")))}
B32: Interval (most common, min) | C32: {=IF($C$28<2,"",IFERROR(_xlfn.LET(_xlpm.t,_xlfn._xlws.FILTER($B$79:$B$10025,$B$79:$B$10025<>""),_xlpm.d,ROUND((_xlfn.DROP(_xlpm.t,1)-_xlfn.DROP(_xlpm.t,-1))*1440,0),IFERROR(MODE(_xlpm.d),MEDIAN(_xlpm.d))),""))} | E32: =IF($C$32="","",IF($C$32<=15,"✔ "&TEXT($C$32,"0")&"-minute intervals","⚠ "&TEXT($C$32,"0")&"-minute intervals — 15 minutes or finer is expected for demand data"))
B33: Max kW (from data) | C33: =IF($C$28=0,"",MAX($C$79:$C$50031)) | E33: =IF($C$33="","","peak at "&TEXT(IFERROR(INDEX($B$79:$B$10025,MATCH($C$33,$C$79:$C$10025,0)),""),"ddd yyyy-mm-dd hh:mm"))
B34: kVAR Coincident with Peak kW | C34: =IF($C$28=0,"",IFERROR(INDEX($D$79:$D$50031,MATCH($C$33,$C$79:$C$50031,0)),""))
B35: Max kVA (from data) | C35: =IF($C$28=0,"",IF(COUNT($E$79:$E$50031)>0,MAX($E$79:$E$50031),IF(ISNUMBER(C34),SQRT(C33^2+C34^2),C33/C7)))
B36: Load Factor (avg ÷ peak) | C36: =IF(OR($C$28=0,$C$33="",$C$33=0),"",AVERAGE($C$79:$C$10025)/$C$33) | E36: =IF($C$36="","",IF($C$36>=0.6,"steady load — peak is representative",IF($C$36>=0.35,"typical commercial profile","peaky load — the 125% figure is driven by short spikes, worth reviewing the duration curve")))
A38: COMPLIANCE & SEASONAL ADJUSTMENT
B40: Recording taken during period of maximum loading? | D40: {=IF(C40="Yes","✓",("⚠ NEC "&NECREF("220.87")&"(2): data must be taken while the building is at its period of maximum loading"))} -> ⚠ NEC 220.87(2): data must be taken while the building is at its period of maximum loading
B41: Seasonal / Periodic Load Adjustment Factor | C41: 1 | D41: Multiplier on peak to account for seasonal/periodic loads not energized during the recording (e.g., heating logged in summer). 1.00 = no adjustment.
A43: {="RESULTS — NEC "&NECREF("220.87")&" EXISTING LOAD"} -> RESULTS — NEC 220.87 EXISTING LOAD
B45: Governing Peak kW | C45: =IF($C$6="Manual Peak Entry",IF(C20="",0,C20),IF(C28=0,0,C33)) -> 0
B46: Governing Peak kVA | C46: =IF($C$6="Manual Peak Entry",IF(C24="",0,C24),IF(C28=0,0,C35)) -> 0
B47: Seasonally Adjusted Peak kVA | C47: =C46*C41 -> 0
B48: {="NEC "&NECREF("220.87")&" Existing Load = 125% × Adjusted Peak (kVA)"} -> NEC 220.87 Existing Load = 125% × Adjusted Peak (kVA) | C48: =C47*1.25 -> 0
B49: {="NEC "&NECREF("220.87")&" Existing Load (A)"} -> NEC 220.87 Existing Load (A) | C49: =IF(OR(C48=0,N(C8)=0),"",C48*1000/IF(C9=3,C8*SQRT(3),C8))
...

Sheet Generator
A1: GENERATOR SIZING — NEC 700 / 701 / 702
B2: Project: | C2: =IF(Dashboard!B7="","—",Dashboard!B7) -> — | G2: Service Voltage: | H2: =IF(Dashboard!$C$38="","",Dashboard!$C$38)
A4: SETTINGS
B6: Generator Rated PF | C6: 0.8 | E6: Design Margin (×) | F6: 1.2 | H6: Assumed Load PF (kVA→kW) | I6: 0.9 | K6: Sizing Basis (ATS & Gen) | L6: Calculated Demand
A8: LOADS FROM LOAD CALC (Gen = Y)
B9: Section | C9: Connected kVA | D9: Include?
B10: Site / Exterior | C10: {=INDEX(LC_GenByCategory,ROW()-ROW($B$9))} -> 0 | D10: Y
B11: House / Misc | C11: {=INDEX(LC_GenByCategory,ROW()-ROW($B$9))} -> 0 | D11: Y
B12: Department / Owner | C12: {=INDEX(LC_GenByCategory,ROW()-ROW($B$9))} -> 0 | D12: Y
B13: Refrigeration | C13: {=INDEX(LC_GenByCategory,ROW()-ROW($B$9))} -> 0 | D13: Y
B14: Mechanical | C14: {=INDEX(LC_GenByCategory,ROW()-ROW($B$9))} -> 0 | D14: Y
B15: Plumbing | C15: {=INDEX(LC_GenByCategory,ROW()-ROW($B$9))} -> 0 | D15: Y
B16: Kitchen / Food Service | C16: {=INDEX(LC_GenByCategory,ROW()-ROW($B$9))} -> 0 | D16: Y
B17: Elevators / Conveying | C17: {=INDEX(LC_GenByCategory,ROW()-ROW($B$9))} -> 0 | D17: Y
B18: EV Charging | C18: {=INDEX(LC_GenByCategory,ROW()-ROW($B$9))} -> 0 | D18: Y
B19: Data / IT | C19: {=INDEX(LC_GenByCategory,ROW()-ROW($B$9))} -> 0 | D19: Y
B20: Fire / Life Safety | C20: {=INDEX(LC_GenByCategory,ROW()-ROW($B$9))} -> 0 | D20: Y
B21: Process / Industrial | C21: {=INDEX(LC_GenByCategory,ROW()-ROW($B$9))} -> 0 | D21: Y
B23: TOTAL INCLUDED (kVA) | C23: =SUMIF($D$10:$D$21,"Y",$C$10:$C$21) -> 0
A25: ADDITIONAL / MANUAL LOADS
B26: Description | C26: Load Class | D26: Qty | E26: kW each | F26: PF | G26: kW total | H26: kVA | I26: Start Method | J26: Start kVA | K26: Notes | L26: Unit
G27: =IF(OR(GEN_Loads[[#This Row],[Qty]]="",GEN_Loads[[#This Row],[kW each]]=""),"",GEN_Loads[[#This Row],[Qty]]*GEN_Loads[[#This Row],[kW each]]) | H27: =IF(GEN_Loads[[#This Row],[kW total]]="","",GEN_Loads[[#This Row],[kW total]]/IF(GEN_Loads[[#This Row],[PF]]="",0.8,GEN_Loads[[#This Row],[PF]])) | J27: {=IF(GEN_Loads[[#This Row],[kVA]]="","",GEN_Loads[[#This Row],[kVA]]*_xlfn.SWITCH(GEN_Loads[[#This Row],[Start Method]],"Across-the-Line",6,"Soft Start",3,"VFD",1.5,"None",1,1))}
G28: =IF(OR(GEN_Loads[[#This Row],[Qty]]="",GEN_Loads[[#This Row],[kW each]]=""),"",GEN_Loads[[#This Row],[Qty]]*GEN_Loads[[#This Row],[kW each]]) | H28: =IF(GEN_Loads[[#This Row],[kW total]]="","",GEN_Loads[[#This Row],[kW total]]/IF(GEN_Loads[[#This Row],[PF]]="",0.8,GEN_Loads[[#This Row],[PF]])) | J28: {=IF(GEN_Loads[[#This Row],[kVA]]="","",GEN_Loads[[#This Row],[kVA]]*_xlfn.SWITCH(GEN_Loads[[#This Row],[Start Method]],"Across-the-Line",6,"Soft Start",3,"VFD",1.5,"None",1,1))}
G29: =IF(OR(GEN_Loads[[#This Row],[Qty]]="",GEN_Loads[[#This Row],[kW each]]=""),"",GEN_Loads[[#This Row],[Qty]]*GEN_Loads[[#This Row],[kW each]]) | H29: =IF(GEN_Loads[[#This Row],[kW total]]="","",GEN_Loads[[#This Row],[kW total]]/IF(GEN_Loads[[#This Row],[PF]]="",0.8,GEN_Loads[[#This Row],[PF]])) | J29: {=IF(GEN_Loads[[#This Row],[kVA]]="","",GEN_Loads[[#This Row],[kVA]]*_xlfn.SWITCH(GEN_Loads[[#This Row],[Start Method]],"Across-the-Line",6,"Soft Start",3,"VFD",1.5,"None",1,1))}
G30: =IF(OR(GEN_Loads[[#This Row],[Qty]]="",GEN_Loads[[#This Row],[kW each]]=""),"",GEN_Loads[[#This Row],[Qty]]*GEN_Loads[[#This Row],[kW each]]) | H30: =IF(GEN_Loads[[#This Row],[kW total]]="","",GEN_Loads[[#This Row],[kW total]]/IF(GEN_Loads[[#This Row],[PF]]="",0.8,GEN_Loads[[#This Row],[PF]])) | J30: {=IF(GEN_Loads[[#This Row],[kVA]]="","",GEN_Loads[[#This Row],[kVA]]*_xlfn.SWITCH(GEN_Loads[[#This Row],[Start Method]],"Across-the-Line",6,"Soft Start",3,"VFD",1.5,"None",1,1))}
G31: =IF(OR(GEN_Loads[[#This Row],[Qty]]="",GEN_Loads[[#This Row],[kW each]]=""),"",GEN_Loads[[#This Row],[Qty]]*GEN_Loads[[#This Row],[kW each]]) | H31: =IF(GEN_Loads[[#This Row],[kW total]]="","",GEN_Loads[[#This Row],[kW total]]/IF(GEN_Loads[[#This Row],[PF]]="",0.8,GEN_Loads[[#This Row],[PF]])) | J31: {=IF(GEN_Loads[[#This Row],[kVA]]="","",GEN_Loads[[#This Row],[kVA]]*_xlfn.SWITCH(GEN_Loads[[#This Row],[Start Method]],"Across-the-Line",6,"Soft Start",3,"VFD",1.5,"None",1,1))}
G32: =IF(OR(GEN_Loads[[#This Row],[Qty]]="",GEN_Loads[[#This Row],[kW each]]=""),"",GEN_Loads[[#This Row],[Qty]]*GEN_Loads[[#This Row],[kW each]]) | H32: =IF(GEN_Loads[[#This Row],[kW total]]="","",GEN_Loads[[#This Row],[kW total]]/IF(GEN_Loads[[#This Row],[PF]]="",0.8,GEN_Loads[[#This Row],[PF]])) | J32: {=IF(GEN_Loads[[#This Row],[kVA]]="","",GEN_Loads[[#This Row],[kVA]]*_xlfn.SWITCH(GEN_Loads[[#This Row],[Start Method]],"Across-the-Line",6,"Soft Start",3,"VFD",1.5,"None",1,1))}
G33: =IF(OR(GEN_Loads[[#This Row],[Qty]]="",GEN_Loads[[#This Row],[kW each]]=""),"",GEN_Loads[[#This Row],[Qty]]*GEN_Loads[[#This Row],[kW each]]) | H33: =IF(GEN_Loads[[#This Row],[kW total]]="","",GEN_Loads[[#This Row],[kW total]]/IF(GEN_Loads[[#This Row],[PF]]="",0.8,GEN_Loads[[#This Row],[PF]])) | J33: {=IF(GEN_Loads[[#This Row],[kVA]]="","",GEN_Loads[[#This Row],[kVA]]*_xlfn.SWITCH(GEN_Loads[[#This Row],[Start Method]],"Across-the-Line",6,"Soft Start",3,"VFD",1.5,"None",1,1))}
G34: =IF(OR(GEN_Loads[[#This Row],[Qty]]="",GEN_Loads[[#This Row],[kW each]]=""),"",GEN_Loads[[#This Row],[Qty]]*GEN_Loads[[#This Row],[kW each]]) | H34: =IF(GEN_Loads[[#This Row],[kW total]]="","",GEN_Loads[[#This Row],[kW total]]/IF(GEN_Loads[[#This Row],[PF]]="",0.8,GEN_Loads[[#This Row],[PF]])) | J34: {=IF(GEN_Loads[[#This Row],[kVA]]="","",GEN_Loads[[#This Row],[kVA]]*_xlfn.SWITCH(GEN_Loads[[#This Row],[Start Method]],"Across-the-Line",6,"Soft Start",3,"VFD",1.5,"None",1,1))}
G35: =IF(OR(GEN_Loads[[#This Row],[Qty]]="",GEN_Loads[[#This Row],[kW each]]=""),"",GEN_Loads[[#This Row],[Qty]]*GEN_Loads[[#This Row],[kW each]]) | H35: =IF(GEN_Loads[[#This Row],[kW total]]="","",GEN_Loads[[#This Row],[kW total]]/IF(GEN_Loads[[#This Row],[PF]]="",0.8,GEN_Loads[[#This Row],[PF]])) | J35: {=IF(GEN_Loads[[#This Row],[kVA]]="","",GEN_Loads[[#This Row],[kVA]]*_xlfn.SWITCH(GEN_Loads[[#This Row],[Start Method]],"Across-the-Line",6,"Soft Start",3,"VFD",1.5,"None",1,1))}
G36: =IF(OR(GEN_Loads[[#This Row],[Qty]]="",GEN_Loads[[#This Row],[kW each]]=""),"",GEN_Loads[[#This Row],[Qty]]*GEN_Loads[[#This Row],[kW each]]) | H36: =IF(GEN_Loads[[#This Row],[kW total]]="","",GEN_Loads[[#This Row],[kW total]]/IF(GEN_Loads[[#This Row],[PF]]="",0.8,GEN_Loads[[#This Row],[PF]])) | J36: {=IF(GEN_Loads[[#This Row],[kVA]]="","",GEN_Loads[[#This Row],[kVA]]*_xlfn.SWITCH(GEN_Loads[[#This Row],[Start Method]],"Across-the-Line",6,"Soft Start",3,"VFD",1.5,"None",1,1))}
A38: SIZING SUMMARY
B40: Total Running kVA | D40: =ROUND(SUM($J$53:$J$58),1) -> 0
B41: Total Running kW | D41: =ROUND(SUM($K$53:$K$58),1) -> 0
B42: Max Single-Step Starting kVA | D42: =MAX($L$53:$L$58) -> 0
B43: Required kW = Σ per-unit (Running kW × Margin) | D43: =ROUND(SUM($M$53:$M$58),1) -> 0
B44: Required kVA = Σ per-unit max(Running kVA × Margin, Start kVA) | D44: =ROUND(SUM($N$53:$N$58),1) -> 0
B45: TOTAL SUGGESTED GENERATOR (kW) — all units / banks | D45: =IF(SUMIFS($R$53:$R$58,$Q$53:$Q$58,"Y")=0,"—",SUMIFS($R$53:$R$58,$Q$53:$Q$58,"Y")) -> —
B46: Total Generator kVA @ Rated PF | D46: =IF(ISNUMBER($D$45),ROUND(SUMIFS($S$53:$S$58,$Q$53:$Q$58,"Y"),0),"—") -> —
A48: Starting-kVA multipliers are typical (ATL×6, Soft×3, VFD×1.5). Verify against equipment data; largest single step drives voltage-dip sizing.
...

Sheet UPS
A1: UPS SIZING — CRITICAL / CONTINUOUS LOADS
B2: Project: | C2: =IF(Dashboard!B7="","—",Dashboard!B7) -> — | G2: Service Voltage: | H2: =IF(Dashboard!$C$38="","",Dashboard!$C$38)
A4: SETTINGS
B6: UPS Output PF | C6: 0.9 | E6: Design Margin (×) | F6: 1.25 | G6: Redundancy | H6: N | J6: Runtime Target (min) | K6: 10 | M6: Typ. UPS SCCR (A) | N6: 65000
A8: LOADS FROM LOAD CALC (UPS = Y)
B9: Section | C9: Connected kVA | D9: Include?
B10: Site / Exterior | C10: {=INDEX(LC_UPSByCategory,ROW()-ROW($B$9))} -> 0 | D10: Y
B11: House / Misc | C11: {=INDEX(LC_UPSByCategory,ROW()-ROW($B$9))} -> 0 | D11: Y
B12: Department / Owner | C12: {=INDEX(LC_UPSByCategory,ROW()-ROW($B$9))} -> 0 | D12: Y
B13: Refrigeration | C13: {=INDEX(LC_UPSByCategory,ROW()-ROW($B$9))} -> 0 | D13: Y
B14: Mechanical | C14: {=INDEX(LC_UPSByCategory,ROW()-ROW($B$9))} -> 0 | D14: Y
B15: Plumbing | C15: {=INDEX(LC_UPSByCategory,ROW()-ROW($B$9))} -> 0 | D15: Y
B16: Kitchen / Food Service | C16: {=INDEX(LC_UPSByCategory,ROW()-ROW($B$9))} -> 0 | D16: Y
B17: Elevators / Conveying | C17: {=INDEX(LC_UPSByCategory,ROW()-ROW($B$9))} -> 0 | D17: Y
B18: EV Charging | C18: {=INDEX(LC_UPSByCategory,ROW()-ROW($B$9))} -> 0 | D18: Y
B19: Data / IT | C19: {=INDEX(LC_UPSByCategory,ROW()-ROW($B$9))} -> 0 | D19: Y
B20: Fire / Life Safety | C20: {=INDEX(LC_UPSByCategory,ROW()-ROW($B$9))} -> 0 | D20: Y
